Workbook
Name Age_Car: [1]CustomerDataSet!#REF!
Name Alarm: [1]CustomerDataSet!#REF!
Name Car_Val: [1]CustomerDataSet!#REF!
Name Eng_Type: [1]CustomerDataSet!#REF!
Name EstKmsYear: [1]CustomerDataSet!#REF!
Name Excess: [1]CustomerDataSet!#REF!
Name Exclusions: [1]CustomerDataSet!#REF!
Name Exist_Dam: [1]CustomerDataSet!#REF!
Name Ins_Type: [1]CustomerDataSet!#REF!
Name Lic_Held: [1]CustomerDataSet!#REF!
Name Lic_Type: [1]CustomerDataSet!#REF!
Name Park_Onight: [1]CustomerDataSet!#REF!
Name Prev_Ins_Cost: [1]CustomerDataSet!#REF!
Name Quote_Val: [1]CustomerDataSet!#REF!

Sheet Copyright  
B1: DEAKIN UNIVERSITY 2024
A2: You must not otherwise copy or share any part of this document for any other purpose except as expressly permitted under your local copyright laws or with Deakin University's prior consent.

Sheet Data Description
A1: Variable Name | B1: Description
A2: State | B2: The state in which the EV owner normally resides
A3: Locality | B3: EV owners live in the city (Metro) or in the country (Regional)
A4: Age | B4: EV owner’s Age (in years)
A5: Household_Type | B5: Household Type (Single Person, Single Parent, Couple with Children, Couple with no Children)
A6: Annual_KM | B6: Estimate of EV Km travelled per year (Km).
A7: Trip_Type | B7: What type of trips is EV used for? (Work, Private, Holiday)
A8: Reason | B8: Reason to buy the EV (Technology, Environment, Economic, Fuel Security, Health)
A9: EV_Towing | B9: EV is/can be used for Towing (Yes or No)
A10: Charge_at_work | B10: Number of times charging at work per week
A11: Charge_at_Home | B11: Number of times charging at home per week
A12: Calculate_Savings | B12: EV owner actively calculates fuel/Maintenance savings (Yes or No)
... A14: Maintenance_Savings | B14: Estimate of Annual Maintenance Savings ($)

Sheet EVSurvey 
A1: Index | B1: State | C1: Locality | D1: Age | E1: Household_Type | F1: Annual_KM | G1: Trip_Type | H1: Reason | I1: EV_Towing | J1: Charge_at_Work | K1: Charge_at_Home | L1: Calculate_Savings | M1: Fuel_Savings | N1: Maintenance_Savings | O1: Charge_at_home_N
A2: 1 | B2: Queensland | C2: Metro | D2: 45 | E2: Couple with Children | F2: 15000 | G2: Work | H2: Environment | I2: No | J2: 3 | K2: 7 | L2: No | M2: 4000 | N2: 600 | O2: =IF(K2>=5,"More than 5 times per week", "Less than 5 times per week") -> More than 5 times per week
A3: 2 | B3: Tasmania | C3: Regional | D3: 32 | E3: Couple with Children | F3: 12000 | G3: Private | H3: Technology | I3: Yes | J3: 2 | K3: 5 | L3: Yes | M3: 3000 | N3: 750 | O3: =IF(K3>=5,"More than 5 times per week", "Less than 5 times per week") -> More than 5 times per week
A4: 3 | B4: New South Wales | C4: Metro | D4: 50 | E4: Couple with no Children | F4: 10000 | G4: Holiday | H4: Economic | I4: Yes | J4: 4 | K4: 6 | L4: Yes | M4: 3500 | N4: 700 | O4: =IF(K4>=5,"More than 5 times per week", "Less than 5 times per week") -> More than 5 times per week
A5: 4 | B5: Victoria | C5: Regional | D5: 28 | E5: Single Person | F5: 8000 | G5: Work | H5: Fuel Security | I5: No | J5: 5 | K5: 4 | L5: Yes | M5: 2500 | N5: 850 | O5: =IF(K5>=5,"More than 5 times per week", "Less than 5 times per week") -> Less than 5 times per week
A6: 5 | B6: New South Wales | C6: Metro | D6: 55 | E6: Single Parent | F6: 9000 | G6: Private | H6: Environment | I6: Yes | J6: 3 | K6: 7 | L6: No | M6: 2800 | N6: 800 | O6: =IF(K6>=5,"More than 5 times per week", "Less than 5 times per week") -> More than 5 times per week
A7: 6 | B7: New South Wales | C7: Regional | D7: 40 | E7: Couple with Children | F7: 11000 | G7: Work | H7: Health | I7: Yes | J7: 2 | K7: 5 | L7: No | M7: 3200 | N7: 750 | O7: =IF(K7>=5,"More than 5 times per week", "Less than 5 times per week") -> More than 5 times per week
A8: 7 | B8: New South Wales | C8: Metro | D8: 38 | E8: Couple with no Children | F8: 13000 | G8: Private | H8: Fuel Security | I8: No | J8: 3 | K8: 6 | L8: No | M8: 3800 | N8: 700 | O8: =IF(K8>=5,"More than 5 times per week", "Less than 5 times per week") -> More than 5 times per week
A9: 8 | B9: Victoria | C9: Regional | D9: 48 | E9: Single Person | F9: 14000 | G9: Holiday | H9: Technology | I9: Yes | J9: 4 | K9: 4 | L9: Yes | M9: 4200 | N9: 650 | O9: =IF(K9>=5,"More than 5 times per week", "Less than 5 times per week") -> Less than 5 times per week
A10: 9 | B10: New South Wales | C10: Metro | D10: 42 | E10: Couple with Children | F10: 16000 | G10: Work | H10: Economic | I10: Yes | J10: 5 | K10: 3 | L10: Yes | M10: 3800 | N10: 750 | O10: =IF(K10>=5,"More than 5 times per week", "Less than 5 times per week") -> Less than 5 times per week
A11: 10 | B11: Victoria | C11: Regional | D11: 30 | E11: Single Parent | F11: 10000 | G11: Private | H11: Environment | I11: Yes | J11: 3 | K11: 6 | L11: No | M11: 2900 | N11: 800 | O11: =IF(K11>=5,"More than 5 times per week", "Less than 5 times per week") -> More than 5 times per week
A12: 11 | B12: Queensland | C12: Metro | D12: 52 | E12: Couple with no Children | F12: 12000 | G12: Holiday | H12: Technology | I12: Yes | J12: 2 | K12: 7 | L12: Yes | M12: 3400 | N12: 700 | O12: =IF(K12>=5,"More than 5 times per week", "Less than 5 times per week") -> More than 5 times per week
A13: 12 | B13: New South Wales | C13: Regional | D13: 35 | E13: Couple with Children | F13: 11000 | G13: Work | H13: Fuel Security | I13: No | J13: 3 | K13: 5 | L13: Yes | M13: 3600 | N13: 750 | O13: =IF(K13>=5,"More than 5 times per week", "Less than 5 times per week") -> More than 5 times per week
... A103: 102 | B103: Victoria | C103: Metro | D103: 31 | E103: Couple with no Children | F103: 13000 | G103: Work | H103: Fuel Security | I103: No | J103: 2 | K103: 6 | L103: No | M103: 3100 | N103: 750 | O103: =IF(K103>=5,"More than 5 times per week", "Less than 5 times per week") -> More than 5 times per week

Sheet Attitude
B1: Attitude Statements
A2: Q1 | B2: The government should prioritise the expansion of public charging infrastructure for electric vehicles.
A3: Q2 | B3: I support government incentives to bolster the development of charging infrastructure for electric vehicles.
A4: Q3 | B4: Government regulations targeting the expansion and accessibility of public charging infrastructure are necessary.
A5: Scale | B5: Strongly Disagree (1) to Strongly Agree (10)
E7: Year 2022 | J7: Year 2023
B8: Q1 | C8: Q2 | D8: Q3 | E8: AttitudeScore | G8: Q1 | H8: Q2 | I8: Q3 | J8: AttitudeScore
A9: Respondent-1 | B9: 7 | C9: 5 | D9: 8 | E9: =AVERAGE(B9:D9) -> 6.6666667 | G9: 6 | H9: 8 | I9: 9 | J9: =AVERAGE(G9:I9) -> 7.6666667
A10: Respondent-2 | B10: 5 | C10: 7 | D10: 5 | E10: =AVERAGE(B10:D10) -> 5.6666667 | G10: 7 | H10: 9 | I10: 8 | J10: =AVERAGE(G10:I10) -> 8
A11: Respondent-3 | B11: 9 | C11: 6 | D11: 6 | E11: =AVERAGE(B11:D11) -> 7 | G11: 8 | H11: 6 | I11: 6 | J11: =AVERAGE(G11:I11) -> 6.6666667
A12: Respondent-4 | B12: 2 | C12: 6 | D12: 3 | E12: =AVERAGE(B12:D12) -> 3.6666667 | G12: 9 | H12: 8 | I12: 7 | J12: =AVERAGE(G12:I12) -> 8
A13: Respondent-5 | B13: 6 | C13: 5 | D13: 9 | E13: =AVERAGE(B13:D13) -> 6.6666667 | G13: 8 | H13: 7 | I13: 5 | J13: =AVERAGE(G13:I13) -> 6.6666667
A14: Respondent-6 | B14: 3 | C14: 9 | D14: 2 | E14: =AVERAGE(B14:D14) -> 4.6666667 | G14: 10 | H14: 9 | I14: 1 | J14: =AVERAGE(G14:I14) -> 6.6666667
A15: Respondent-7 | B15: 8 | C15: 1 | D15: 5 | E15: =AVERAGE(B15:D15) -> 4.6666667 | G15: 2 | H15: 8 | I15: 7 | J15: =AVERAGE(G15:I15) -> 5.6666667
A16: Respondent-8 | B16: 1 | C16: 8 | D16: 10 | E16: =AVERAGE(B16:D16) -> 6.3333333 | G16: 8 | H16: 10 | I16: 8 | J16: =AVERAGE(G16:I16) -> 8.6666667
A17: Respondent-9 | B17: 4 | C17: 5 | D17: 7 | E17: =AVERAGE(B17:D17) -> 5.3333333 | G17: 7 | H17: 6 | I17: 1 | J17: =AVERAGE(G17:I17) -> 4.6666667
A18: Respondent-10 | B18: 7 | C18: 7 | D18: 4 | E18: =AVERAGE(B18:D18) -> 6 | G18: 10 | H18: 9 | I18: 1 | J18: =AVERAGE(G18:I18) -> 6.6666667
A19: Respondent-11 | B19: 5 | C19: 5 | D19: 8 | E19: =AVERAGE(B19:D19) -> 6 | G19: 8 | H19: 8 | I19: 6 | J19: =AVERAGE(G19:I19) -> 7.3333333
A20: Respondent-12 | B20: 7 | C20: 4 | D20: 1 | E20: =AVERAGE(B20:D20) -> 4 | G20: 7 | H20: 4 | I20: 5 | J20: =AVERAGE(G20:I20) -> 5.3333333

Sheet Experiment
A1: Index | B1: State | C1: Locality | D1: Age | E1: Household_Type | F1: Annual_KM | G1: Trip_Type | H1: Reason | I1: EV_Towing | J1: Charge_at_Work | K1: Charge_at_Home | L1: Calculate_Savings | M1: Fuel_Savings | N1: Maintenance_Savings
A2: A1 | B2: Queensland | C2: Metro | D2: 45 | E2: Couple with Children | F2: 15000 | G2: Work | H2: Environment | I2: No | J2: 3 | K2: 7 | L2: No | M2: 4000 | N2: 600
A3: A2 | B3: New South Wales | C3: Metro | D3: 50 | E3: Couple with no Children | F3: 10000 | G3: Holiday | H3: Economic | I3: Yes | J3: 4 | K3: 6 | L3: Yes | M3: 3500 | N3: 700
A4: A3 | B4: New South Wales | C4: Metro | D4: 55 | E4: Single Parent | F4: 10000 | G4: Private | H4: Environment | I4: Yes | J4: 3 | K4: 7 | L4: No | M4: 2800 | N4: 800
A5: A4 | B5: New South Wales | C5: Regional | D5: 38 | E5: Couple with no Children | F5: 9000 | G5: Private | H5: Environment | I5: No | J5: 3 | K5: 6 | L5: No | M5: 3800 | N5: 700
A6: A5 | B6: New South Wales | C6: Metro | D6: 42 | E6: Couple with Children | F6: 16000 | G6: Work | H6: Economic | I6: Yes | J6: 5 | K6: 3 | L6: Yes | M6: 3800 | N6: 750
A7: A6 | B7: Victoria | C7: Regional | D7: 30 | E7: Single Parent | F7: 15000 | G7: Private | H7: Environment | I7: Yes | J7: 3 | K7: 6 | L7: No | M7: 2900 | N7: 800
A8: A7 | B8: Queensland | C8: Regional | D8: 33 | E8: Single Parent | F8: 8000 | G8: Holiday | H8: Fuel Security | I8: No | J8: 5 | K8: 6 | L8: No | M8: 2600 | N8: 850
A9: A8 | B9: Queensland | C9: Regional | D9: 37 | E9: Couple with no Children | F9: 12000 | G9: Private | H9: Economic | I9: Yes | J9: 3 | K9: 6 | L9: Yes | M9: 3300 | N9: 750
A10: A9 | B10: New South Wales | C10: Metro | D10: 45 | E10: Single Person | F10: 14000 | G10: Holiday | H10: Environment | I10: Yes | J10: 4 | K10: 7 | L10: No | M10: 3700 | N10: 700
A11: A10 | B11: Western Australia | C11: Regional | D11: 50 | E11: Couple with Children | F11: 15000 | G11: Private | H11: Economic | I11: No | J11: 3 | K11: 6 | L11: No | M11: 3000 | N11: 800
A12: A11 | B12: New South Wales | C12: Regional | D12: 29 | E12: Couple with no Children | F12: 10000 | G12: Holiday | H12: Technology | I12: Yes | J12: 4 | K12: 5 | L12: Yes | M12: 3500 | N12: 750
A13: A12 | B13: Victoria | C13: Metro | D13: 53 | E13: Single Person | F13: 10000 | G13: Work | H13: Economic | I13: Yes | J13: 2 | K13: 7 | L13: Yes | M13: 2700 | N13: 850
... A31: A30 | B31: New South Wales | C31: Regional | D31: 29 | E31: Single Parent | F31: 9000 | G31: Work | H31: Economic | I31: Yes | J31: 4 | K31: 5 | L31: Yes | M31: 3300 | N31: 800

Sheet Question 1
A1: Question 1
F3: Hypothesis Test for µ1 - µ2 (independent, equal variances) | K3: Confidence Interval for µ1 - µ2 (independent, equal variances)
Q4: > | R4: ≤
B5: Metro EV owners | C5: Regional EV Owners | F5: Hypotheses | K5: Level of Confidence | Q5: < | R5: ≥
F6: Null Hypothesis | G6: µ1 - µ2 | H6: =IF(H7=">",$R$4,IF(H7="<",$R$5,$R$6)) -> ≤ | I6: =I7 -> 0 | K6: Level of Confidence | N6: 0.05 | Q6: ≠ | R6: =
A7: Mean | B7: 12090.909 | C7: 11297.872 | F7: Alternative Hypothesis | G7: µ1 - µ2 | H7: > | I7: 0
A8: Standard Error | B8: 320.21955 | C8: 331.6693 | F8: Test Type | I8: =IF(H7="<","Lower",IF(H7=">","Upper","Two")) -> Upper | K8: Sample Results
A9: Median | B9: 12000 | C9: 11000 | F9: Level of significance | K9: Sample 1 Data
A10: Mode | B10: 12000 | C10: 11000 | H10: α | I10: 0.05 | K10: Sample Standard Deviation | N10: =B11 -> 2374.8117
A11: Standard Deviation | B11: 2374.8117 | C11: 2273.8102 | F11: Critical Region | K11: Sample Mean | N11: =B7 -> 12090.909
A12: Sample Variance | B12: 5639730.6 | C12: 5170212.8 | F12: Degrees of Freedom | I12: =I19+I23-2 -> 100 | K12: Sample Size | N12: =B19 -> 55
A13: Kurtosis | B13: -0.67433493 | C13: -0.87909466 | F13: =IF(H6="=","Lower Critical Value","Critical Value") -> Critical Value | I13: =IF(I8="Two",-(TINV(I10,I12)),IF(I8="Lower",-(TINV(I10*2,I12)),TINV(I10*2,I12))) -> 1.6602343 | K13: Sample 2 Data
A14: Skewness | B14: 0.094557586 | C14: 0.29787298 | F14: =IF(H6="=","Upper Critical Value","") | I14: =IF(H6="=",-I13,"") | K14: Sample Standard Deviation | N14: =C11 -> 2273.8102
A15: Range | B15: 10000 | C15: 8000 | F15: Sample Results | K15: Sample Mean | N15: =C7 -> 11297.872
A16: Minimum | B16: 8000 | C16: 8000 | F16: Sample 1 Data | K16: Sample Size | N16: =C19 -> 47
A17: Maximum | B17: 18000 | C17: 16000 | F17: Sample Standard Deviation | I17: =B11 -> 2374.8117
A18: Sum | B18: 665000 | C18: 531000 | F18: Sample Mean | I18: =B7 -> 12090.909 | K18: Intermediate Calculations
A19: Count | B19: 55 | C19: 47 | F19: Sample Size | I19: =B19 -> 55 | K19: Degrees of Freedom | N19: =N12+N16-2 -> 100
F20: Sample 2 Data | K20: Pooled Variance | N20: =((N12-1)*N10^2+(N16-1)*N14^2)/N19 -> 5423752.4
A21: Assumption | B21: Equal variances because the standard deviation of annual distance travlelled by metro EV owners are not more than double that of regional EV owners | F21: Sample Standard Deviation | I21: =C11 -> 2273.8102 | K21: Standard Error of the Mean | N21: =SQRT(N20*(1/N12+1/N16)) -> 462.61503
A22: Null Hypothesis | B22: Metro EV owners travel less than or equal to their regional counterparts | F22: Sample Mean | I22: =C7 -> 11297.872 | K22: t value | N22: =TINV(1-N6,N19) -> 0.062864359
A23: Alternative Hypothesis | B23: Metro EV owners travel further than their regional counterparts | F23: Sample Size | I23: =C19 -> 47
A24: Decision | B24: At 5% level of significance, there is sufficient evidence to conclude that EV owners travel further than their regional counterparts. | K24: Confidence Interval for µ1 - µ2
F25: Pooled Variance | I25: =((I19-1)*I17^2+(I23-1)*I21^2)/I12 -> 5423752.4 | K25: Interval Lower Limit | N25: =(N11-N15)-N22*N21 -> 763.95475
F26: Standard Error of the Mean | I26: =SQRT(I25*(1/I19+1/I23)) -> 462.61503 | K26: Interval Upper Limit | N26: =(N11-N15)+N22*N21 -> 822.11875
F27: t Sample Statistic | I27: =((I18-I22)-I6)/I26 -> 1.7142477
F28: p-value | I28: =IF(H6="=",TDIST(ABS(I27),I12,2),IF(I27*I13>0,TDIST(ABS(I27),I12,1),1-TDIST(ABS(I27),I12,1))) -> 0.044790564
F30: Decision
F31: =IF(I28<I10,"Reject Null Hypothesis", "Fail to reject Null Hypothesis") -> Reject Null Hypothesis

Sheet Question 2
A1: Question 2 | F1: Hypothesis Test for π1 - π2
A3: Count of EV_Towing | B3: Column Labels | F3: Hypotheses | L3: > | M3: ≤
A4: Row Labels | B4: No | C4: Yes | D4: Grand Total | F4: Null Hypothesis | G4: π1 - π2 | H4: =IF(H5=">",M3,IF(H5="<",M4,M5)) -> ≥ | I4: 0 | L4: < | M4: ≥
A5: Metro | B5: 19 | C5: 36 | D5: 55 | F5: Alternative Hypothesis | G5: π1 - π2 | H5: < | I5: 0 | L5: ≠ | M5: =
A6: Regional | B6: 10 | C6: 37 | D6: 47 | F6: Test Type | I6: =IF(H5="<","Lower",IF(H5=">","Upper","Two")) -> Lower
A7: Grand Total | B7: 29 | C7: 73 | D7: 102 | F7: Level of significance
H8: α | I8: 0.05
F9: Critical Region
F10: =IF(H4="=","Lower Critical Value","Critical Value") -> Critical Value | I10: =IF(I6="Two",NORMSINV(I8/2),IF(I6="Lower",NORMSINV(I8),NORMSINV(1-I8))) -> -1.6448536
A11: H0 | B11: There are more or the same number of EV owners in metro areas using their vehicles for towing than those in regional areas | F11: =IF(H4="=","Upper Critical Value","") | I11: =IF(H4="=",-I10,"")
A12: H1 | B12: There are fewer EV owners in metro areas using their vehicles for towing than those in regional areas | F12: Sample Data
A13: Decision | B13: At 5% level of significance, there are not enough evidence to conclude that there are fewer EV owners in metro areas using their vehicles for towing than those in regional areas | F13: Sample 1 Data
F14: Sample Size | I14: 55
F15: Count of 'Successes' | I15: =36/55 -> 0.65454545
F16: Sample proportion, p1 | I16: =I15/I14 -> 0.011900826
F17: Sample 2 Data
F18: Sample Size | I18: 47
F19: Count of 'Successes' | I19: =37/47 -> 0.78723404
F20: Sample proportion, p2 | I20: =I19/I18 -> 0.01674966
F23: Pooled estimate of proportion | I23: =(I15+I19)/(I14+I18) -> 0.014135093
F24: Standard Error | I24: =SQRT(I23*(1-I23)*(1/I14+1/I18)) -> 0.02344919
F25: z Sample Statistic | I25: =((I16-I20)-I4)/I24 -> -0.20678045
F26: p-value | I26: =IF(I6="Two",2*(1-NORMSDIST(ABS(I25))),IF(I6="Lower",NORMSDIST(I25),1-NORMSDIST((I25)))) -> 0.41809066
F28: Decision
F29: =IF(I26<I8,"Reject Null Hypothesis", "Fail to reject Null Hypothesis") -> Fail to reject Null Hypothesis

Sheet Question 3
A1: Question 3
B3: Couple with children | C3: Couple with no children | D3: Single parent | E3: Single person | I3: Anova: Single Factor
B4: 4000 | C4: 3500 | D4: 2800 | E4: 2500
B5: 3000 | C5: 3800 | D5: 2900 | E5: 4200 | I5: SUMMARY
B6: 3200 | C6: 3400 | D6: 2600 | E6: 4100 | I6: Groups | J6: Count | K6: Sum | L6: Average | M6: Variance
B7: 3800 | C7: 3300 | D7: 4300 | E7: 3700 | I7: Couple with children | J7: 30 | K7: 109600 | L7: 3653.3333 | M7: 201195.4
B8: 3600 | C8: 3500 | D8: 3200 | E8: 2700 | I8: Couple with no children | J8: 26 | K8: 90100 | L8: 3465.3846 | M8: 135953.85
B9: 3900 | C9: 3700 | D9: 3300 | E9: 2800 | I9: Single parent | J9: 23 | K9: 73800 | L9: 3208.6957 | M9: 288102.77
B10: 3000 | C10: 4200 | D10: 3600 | E10: 3100 | I10: Single person | J10: 23 | K10: 77800 | L10: 3382.6087 | M10: 282411.07
B11: 3400 | C11: 3500 | D11: 2000 | E11: 3900
B12: 3800 | C12: 3800 | D12: 3200 | E12: 2700
B13: 3100 | C13: 3500 | D13: 3900 | E13: 3600 | I13: ANOVA
B14: 4500 | C14: 2800 | D14: 3400 | E14: 3100 | I14: Source of Variation | J14: SS | K14: df | L14: MS | M14: F | N14: P-value | O14: F crit
B15: 4100 | C15: 3800 | D15: 3300 | E15: 3200 | I15: Between Groups | J15: 2686653.4 | K15: 3 | L15: 895551.14 | M15: 4.0286779 | N15: 0.0095069995 | O15: 2.6974232
B16: 3300 | C16: 3700 | D16: 3600 | E16: 4300 | I16: Within Groups | J16: 21784817 | K16: 98 | L16: 222294.05
B17: 4300 | C17: 2800 | D17: 3200 | E17: 3400
B18: 4200 | C18: 3500 | D18: 3100 | E18: 4200 | I18: Total | J18: 24471471 | K18: 101
B19: 4000 | C19: 3800 | D19: 2000 | E19: 2800
B20: 3900 | C20: 2800 | D20: 3300 | E20: 3500
B21: 4100 | C21: 3800 | D21: 3100 | E21: 3200
B22: 4500 | C22: 3000 | D22: 3900 | E22: 2900 | I22: Tukey Kramer Multiple Comparisons
B23: 3500 | C23: 3800 | D23: 3100 | E23: 3700
B24: 3200 | C24: 3300 | D24: 3600 | E24: 3300 | J24: Sample | K24: Sample | N24: Absolute | O24: Std. Error | P24: Critical
B25: 3500 | C25: 3800 | D25: 3400 | E25: 3200 | I25: Group | J25: Mean | K25: Size | M25: Comparison | N25: Difference | O25: of Difference | P25: Range | Q25: =IF(J36="","Results are NOT valid until Q Statistic is entered into B15","Results") -> Results
B26: 3700 | C26: 3200 | D26: 3000 | E26: 3700 | I26: =B3 -> Couple with children | J26: =B37 -> 3653.3333 | K26: =J7 -> 30 | M26: Group 1 to Group 2 | N26: =ABS($J$26-J27) -> 187.94872 | O26: =SQRT(($J$35/2)*((1/$K$26)+(1/K27))) -> 89.329651 | P26: =$J$36*O26 -> 329.62641 | Q26: =IF(N26>P26,"Means are different","Means are not different") -> Means are not different
B27: 3400 | C27: 3100 | I27: =C3 -> Couple with no children | J27: =C37 -> 3465.3846 | K27: =J8 -> 26 | M27: Group 1 to Group 3 | N27: =ABS($J$26-J28) -> 444.63768 | O27: =SQRT(($J$35/2)*((1/$K$26)+(1/K28))) -> 92.397945 | P27: =$J$36*O27 -> 340.94842 | Q27: =IF(N27>P27,"Means are different","Means are not different") -> Means are different
B28: 3700 | C28: 3600 | I28: =D3 -> Single parent | J28: =D37 -> 3208.6957 | K28: =J9 -> 23 | M28: Group 1 to Group 4 | N28: =ABS($J$26-J29) -> 270.72464 | O28: =SQRT(($J$35/2)*((1/$K$26)+(1/K29))) -> 92.397945 | P28: =$J$36*O28 -> 340.94842 | Q28: =IF(N28>P28,"Means are different","Means are not different") -> Means are not different
B29: 3500 | C29: 3100 | I29: =E3 -> Single person | J29: =E37 -> 3382.6087 | K29: =J10 -> 23 | M29: Group 2 to Group 3 | N29: =ABS($J$27-J28) -> 256.68896 | O29: =SQRT(($J$35/2)*((1/$K$27)+(1/K28))) -> 95.432516 | P29: =$J$36*O29 -> 352.14598 | Q29: =IF(N29>P29,"Means are different","Means are not different") -> Means are not different
B30: 3300 | M30: Group 2 to Group 4 | N30: =ABS($J$27-J29) -> 82.77592 | O30: =SQRT(($J$35/2)*((1/$K$27)+(1/K29))) -> 95.432516 | P30: =$J$36*O30 -> 352.14598 | Q30: =IF(N30>P30,"Means are different","Means are not different") -> Means are not different
B31: 3900 | I31: Other Data | M31: Group 3 to Group 4 | N31: =ABS(J28-J29) -> 173.91304 | O31: =SQRT(($J$35/2)*((1/K28)+(1/K29))) -> 98.310522 | P31: =$J$36*O31 -> 362.76583 | Q31: =IF(N31>P31,"Means are different","Means are not different") -> Means are not different
B32: 2800 | I32: Level of significance | J32: 0.05
B33: 3400 | I33: Numerator d.f. | J33: 4
I34: Denominator d.f. | J34: =K16 -> 98
B35: Couple with children | C35: Couple with no children | D35: Single parent | E35: Single person | I35: MSW | J35: =L16 -> 222294.05
I36: Q Statistic | J36: 3.69
A37: Mean | B37: 3653.3333 | C37: 3465.3846 | D37: 3208.6957 | E37: 3382.6087
A38: Standard Error | B38: 81.893305 | C38: 72.311784 | D38: 111.92054 | E38: 110.80949
A39: Median | B39: 3650 | C39: 3500 | D39: 3200 | E39: 3300
A40: Mode | B40: 3900 | C40: 3800 | D40: 3200 | E40: 3700
A41: Standard Deviation | B41: 448.5481 | C41: 368.7192 | D41: 536.75205 | E41: 531.42362
...

Sheet Question 4
A1: Count of Charge_at_home_N | B1: Column Labels
A2: Row Labels | B2: Economic | C2: Environment | D2: Fuel Security | E2: Health | F2: Technology | G2: Grand Total
A3: Less than 5 times per week | B3: 4 | C3: 2 | D3: 6 | E3: 4 | F3: 4 | G3: 20
A4: More than 5 times per week | B4: 13 | C4: 16 | D4: 24 | E4: 13 | F4: 16 | G4: 82
A5: Grand Total | B5: 17 | C5: 18 | D5: 30 | E5: 17 | F5: 20 | G5: 102
A8: Chi-Square Test
A10: Observed Frequencies
B11: Reason to buy the EV | I11: Calculations
A12: Number of times charging at home per week | B12: Economic | C12: Environment | D12: Fuel Security | E12: Health | F12: Technology | G12: Total | I12: fo - fe
A13: Less than 5 times per week | B13: 4 | C13: 2 | D13: 6 | E13: 4 | F13: 4 | G13: =SUM(B13:F13) -> 20 | I13: =B13 - B20 -> 0.66666667 | J13: =C13 - C20 -> -1.5294118 | K13: =D13 - D20 -> 0.11764706 | L13: =E13 - E20 -> 0.66666667 | M13: =F13 - F20 -> 0.078431373
A14: More than 5 times per week | B14: 13 | C14: 16 | D14: 24 | E14: 13 | F14: 16 | G14: =SUM(B14:F14) -> 82 | I14: =B14 - B21 -> -0.66666667 | J14: =C14 - C21 -> 1.5294118 | K14: =D14 - D21 -> -0.11764706 | L14: =E14 - E21 -> -0.66666667 | M14: =F14 - F21 -> -0.078431373
A15: Total | B15: =SUM(B13:B14) -> 17 | C15: =SUM(C13:C14) -> 18 | D15: =SUM(D13:D14) -> 30 | E15: =SUM(E13:E14) -> 17 | F15: =SUM(F13:F14) -> 20 | G15: =SUM(B15:F15) -> 102
B16: :
A17: Expected Frequencies
B18: =B11 -> Reason to buy the EV
A19: =A12 -> Number of times charging at home per week | B19: =B12 -> Economic | C19: =C12 -> Environment | D19: =D12 -> Fuel Security | E19: =E12 -> Health | F19: =F12 -> Technology | G19: Total | I19: (fo - fe)^2/fe
A20: =A13 -> Less than 5 times per week | B20: =$G13 * B15/$G$15 -> 3.3333333 | C20: =$G13 * C15/$G$15 -> 3.5294118 | D20: =$G13 * D15/$G$15 -> 5.8823529 | E20: =$G13 * E15/$G$15 -> 3.3333333 | F20: =$G13 * F15/$G$15 -> 3.9215686 | G20: =SUM(B20:F20) -> 20 | I20: =I13^2/B20 -> 0.13333333 | J20: =J13^2/C20 -> 0.6627451 | K20: =K13^2/D20 -> 0.0023529412 | L20: =L13^2/E20 -> 0.13333333 | M20: =M13^2/F20 -> 0.0015686275
A21: =A14 -> More than 5 times per week | B21: =$G14 * B15/$G$15 -> 13.666667 | C21: =$G14 * C15/$G$15 -> 14.470588 | D21: =$G14 * D15/$G$15 -> 24.117647 | E21: =$G14 * E15/$G$15 -> 13.666667 | F21: =$G14 * F15/$G$15 -> 16.078431 | G21: =SUM(B21:F21) -> 82 | I21: =I14^2/B21 -> 0.032520325 | J21: =J14^2/C21 -> 0.16164515 | K21: =K14^2/D21 -> 0.00057388809 | L21: =L14^2/E21 -> 0.032520325 | M21: =M14^2/F21 -> 0.00038259206
A22: Total | B22: =SUM(B20:B21) -> 17 | C22: =SUM(C20:C21) -> 18 | D22: =SUM(D20:D21) -> 30 | E22: =SUM(E20:E21) -> 17 | F22: =SUM(F20:F21) -> 20 | G22: =SUM(B22:F22) -> 102
A24: Data
A25: Level of Significance | B25: 0.05
A26: Number of Rows | B26: 2
A27: Number of Columns | B27: 5
A28: Degrees of Freedom | B28: =(B26 - 1) * (B27 - 1) -> 4
A30: Results
A31: Critical Value | B31: =CHIINV(B25, B28) -> 9.487729
A32: Chi-Square Test Statistic | B32: =SUM(I20:M21) -> 1.1609756
A33: p-Value | B33: =CHIDIST(B32, B28) -> 0.88448098
A34: =IF(B33<B25, "Reject the null hypothesis", "Do not reject the null hypothesis") -> Do not reject the null hypothesis
A36: Expected frequency assumption
A37: =IF(OR(B20<1, C20<1, D20<1, E20<1, F20<1, B21<1, C21<1, D21<1, E21<1, F21<1), " is violated.", " is met.") -> is met.
A39: H0 | B39: There is no difference in the proportion of EV owners who charge their vehicles at home more than 5 times per week based on their reason for purchasing an EV | F39: π1 = π2 =… = π5 | G39: 1,2,..,5 = Economic, Environment, Fuel Security, Health, Technology
A40: H1 | B40: There is a difference in the proportion of EV owners who charge their vehicles at home more than 5 times per week based on their reason for purchasing an EV | F40: π1 ≠ π2 =… ≠ π5
A41: Decision | B41: At 5% level of signficance, there is insufficient evidence to conclude thatr there is a difference in the proportion of EV owners who charge their vehicles at home more than 5 times per week based on their reason for purchasing an EV

Sheet Question 5
A1: Question 5
A3: Locality | B3: Holiday | C3: Private | D3: Work | G3: Anova: Two-Factor With Replication
A4: Metro | B4: 10000 | C4: 10000 | D4: 15000
B5: 14000 | C5: 10000 | D5: 16000 | G5: SUMMARY | H5: Holiday | I5: Private | J5: Work | K5: Total
B6: 11000 | C6: 11000 | D6: 10000 | G6: Metro
B7: 9000 | C7: 12000 | D7: 10000 | G7: Count | H7: 5 | I7: 5 | J7: 5 | K7: 15
B8: 13000 | C8: 12000 | D8: 14000 | G8: Sum | H8: 57000 | I8: 55000 | J8: 65000 | K8: 177000
A9: Regional | B9: 8000 | C9: 9000 | D9: 10000 | G9: Average | H9: 11400 | I9: 11000 | J9: 13000 | K9: 11800
B10: 10000 | C10: 15000 | D10: 11000 | G10: Variance | H10: 4300000 | I10: 1000000 | J10: 8000000 | K10: 4600000
B11: 14000 | C11: 12000 | D11: 9000
B12: 13000 | C12: 15000 | D12: 11000 | G12: Regional
B13: 12000 | C13: 16000 | D13: 9000 | G13: Count | H13: 5 | I13: 5 | J13: 5 | K13: 15
G14: Sum | H14: 57000 | I14: 67000 | J14: 50000 | K14: 174000
B15: Holiday | C15: Private | D15: Work | E15: Total | G15: Average | H15: 11400 | I15: 13400 | J15: 10000 | K15: 11600
A16: Metro | B16: 11400 | C16: 11000 | D16: 13000 | E16: 11800 | G16: Variance | H16: 5800000 | I16: 8300000 | J16: 1000000 | K16: 6400000
A17: Regional | B17: 11400 | C17: 13400 | D17: 10000 | E17: 11600
A18: Total | B18: 11400 | C18: 12200 | D18: 11500 | G18: Total
G19: Count | H19: 10 | I19: 10 | J19: 10
G20: Sum | H20: 114000 | I20: 122000 | J20: 115000
A21: Test the hypothesis of no difference due to Factor A - Locality | G21: Average | H21: 11400 | I21: 12200 | J21: 11500
A22: Null hypothesis | B22: Mean distances travelled between metro and regional area is no different | G22: Variance | H22: 4488888.9 | I22: 5733333.3 | J22: 6500000
A23: Alternative hypothesis | B23: Mean distances travelled between metro and regional area is diffferent
A25: Test the hypothesis of no difference due to Factor B - Types of Trip | G25: ANOVA
A26: Null hypothesis | B26: Mean distances travelled between three types of trip is no different | G26: Source of Variation | H26: SS | I26: df | J26: MS | K26: F | L26: P-value | M26: F crit
A27: Alternative hypothesis | B27: Mean distances travelled between three types of trip is different | G27: Sample | H27: 300000 | I27: 1 | J27: 300000 | K27: 0.063380282 | L27: 0.8033742 | M27: 4.2596773
G28: Columns | H28: 3800000 | I28: 2 | J28: 1900000 | K28: 0.40140845 | L28: 0.67378729 | M28: 3.4028261
A29: Test the hypothesis of no interaction between A and B | G29: Interaction | H29: 36600000 | I29: 2 | J29: 18300000 | K29: 3.8661972 | L29: 0.035034892 | M29: 3.4028261
A30: Null hypothesis | B30: There is no interaction between locality and types of trip | G30: Within | H30: 113600000 | I30: 24 | J30: 4733333.3
A31: Alternative hypothesis | B31: There is an interaction between locality and types of trip
G32: Total | H32: 154300000 | I32: 29
A34: Conclusion
A36: Main effect of Locality | B36: Because p-value is 0.32 which is more than 0.05, we do not reject H0
B37: There is not sufficient evidence to conclude that the mean distance travelled in Evs is different between Metro EV owners and Regional EV owners
A39: Main effect of trips type | B39: Because p-value is 0.67, which is more than 0.05, we do not reject H0
B40: There is not sufficient evidence to conclude that the mean distance travelled in Evs is different between types of trips
A42: Interaction effect | B42: Because p-value is 0.035, which is less than 0.05, we reject H0
B43: There is sufficient to conclude that there is an interaction between Locality and Types of trips

Sheet Question 6
A1: Question 6
A3: Difference | C3: Differences in attitude | F3: Hypothesis Test for µ1 - µ2 (Dependent) | K3: Confidence Interval for for µ1 - µ2 (Dependent) | N3: > | O3: ≤
A4: =Attitude!J9-Attitude!E9 -> 1 | N4: < | O4: ≥
A5: =Attitude!J10-Attitude!E10 -> 2.3333333 | C5: Mean | D5: 1.2777778 | F5: Hypotheses | K5: Level of Confidence | N5: ≠ | O5: =
A6: =Attitude!J11-Attitude!E11 -> -0.33333333 | C6: Standard Error | D6: 0.39532907 | F6: Null Hypothesis | G6: µD | H6: =IF(H7=">",O3,IF(H7="<",O4,O5)) -> = | I6: =I7 -> 0 | K6: Confidence Level | L6: 0.95
A7: =Attitude!J12-Attitude!E12 -> 4.3333333 | C7: Median | D7: 1.1666667 | F7: Alternative Hypothesis | G7: µD | H7: ≠ | I7: 0
A8: =Attitude!J13-Attitude!E13 -> 0 | C8: Mode | D8: 1 | F8: Test Type | I8: =IF(H7="<","Lower",IF(H7=">","Upper","Two")) -> Two | K8: Sample Data
A9: =Attitude!J14-Attitude!E14 -> 2 | C9: Standard Deviation | D9: 1.3694601 | F9: Level of significance | K9: Sample Standard Deviation of Differences | L9: =D9 -> 1.3694601
A10: =Attitude!J15-Attitude!E15 -> 1 | C10: Sample Variance | D10: 1.8754209 | H10: α | I10: 0.05 | K10: Sample Mean of Differences | L10: =D5 -> 1.2777778
A11: =Attitude!J16-Attitude!E16 -> 2.3333333 | C11: Kurtosis | D11: 1.0638745 | F11: Critical Region | K11: Sample Size | L11: =D17 -> 12
A12: =Attitude!J17-Attitude!E17 -> -0.66666667 | C12: Skewness | D12: 0.73764367 | F12: Degrees of Freedom | I12: =I18-1 -> 11
A13: =Attitude!J18-Attitude!E18 -> 0.66666667 | C13: Range | D13: 5 | F13: =IF(H6="=","Lower Critical Value","Critical Value") -> Lower Critical Value | I13: =IF(I8="Two",-(TINV(I10,I12)),IF(I8="Lower",-(TINV(I10*2,I12)),TINV(I10*2,I12))) -> -2.2009852 | K13: Intermediate Calculations
A14: =Attitude!J19-Attitude!E19 -> 1.3333333 | C14: Minimum | D14: -0.66666667 | F14: =IF(H6="=","Upper Critical Value","") -> Upper Critical Value | I14: =IF(H6="=",-I13,"") -> 2.2009852 | K14: Standard Error of the Mean Differences | L14: =L9/SQRT(L11) -> 0.39532907
A15: =Attitude!J20-Attitude!E20 -> 1.3333333 | C15: Maximum | D15: 4.3333333 | F15: Sample Data | K15: Degrees of Freedom | L15: =L11-1 -> 11
C16: Sum | D16: 15.333333 | F16: Sample Standard Deviation of differences | I16: =D9 -> 1.3694601 | K16: t Value | L16: =TINV(1-L6,L15) -> 2.2009852
C17: Count | D17: 12 | F17: Sample Mean of differences | I17: =D5 -> 1.2777778 | K17: Margin of Error | L17: =L16*L14 -> 0.87011341
F18: Sample Size | I18: =D17 -> 12
A19: Asumption | K19: Confidence Interval
A20: Sample data is normally distributed | F20: Standard Error of the Mean | I20: =I16/SQRT(I18) -> 0.39532907 | K20: Interval Lower Limit | L20: =L10-L17 -> 0.40766436
F21: t Sample Statistic | I21: =(I17-I6)/I20 -> 3.2321878 | K21: Interval Upper Limit | L21: =L10+L17 -> 2.1478912
F22: p-value | I22: =IF(H6="=",TDIST(ABS(I21),I12,2),IF(I21*I13>0,TDIST(ABS(I21),I12,1),1-TDIST(ABS(I21),I12,1))) -> 0.007984102
A24: Null hypothesis | B24: There is no change in the attidue towards public EV charging infrastructure | F24: Decision
A25: Alternative hypothesis | B25: There is a change in the attitude towards public EV charging infrastructure | F25: =IF(I22<I10,"Reject Null Hypothesis", "Fail to reject Null Hypothesis") -> Reject Null Hypothesis
A26: Decision | B26: At 5% level of significance, there is enough evidence to conclude that there is a change in the attitude of towards public EV charging infrastructure
